‚úÖ ChromeDriver encontrado: c:\Users\Ramiro\OneDrive\Documentos\GitHub\Facultad\Ingenieria de Software\Practico Testing\chromedriver.exe
‚úÖ ChromeDriver configurado: c:\Users\Ramiro\OneDrive\Documentos\GitHub\Facultad\Ingenieria de Software\Practico Testing\chromedriver.exe
üöÄ Iniciando driver...
üîÑ Manejo de di√°logos iniciales de Chrome...
‚úÖ Se hizo click en 'Usar sin una cuenta'
‚úÖ Se hizo click en 'M√°s'
‚úÖ Se hizo click en 'Entendido'
üåê Navegando a automationexercise.com...
‚úÖ P√°gina cargada correctamente.
üì± Contextos disponibles: ['NATIVE_APP', 'WEBVIEW_chrome']
üîÑ Cambiando a contexto: WEBVIEW_chrome
‚úÖ ¬°Cambio de contexto exitoso!
El contexto actual es: WEBVIEW_chrome
üîÑ Buscando productos en la p√°gina...
Traceback (most recent call last):
  File "C:\Users\Ramiro\AppData\Local\Programs\Python\Python313\Lib\site-packages\urllib3\connectionpool.py", line 787, in urlopen
    response = self._make_request(
        conn,
    ...<10 lines>...
        **response_kw,
    )
  File "C:\Users\Ramiro\AppData\Local\Programs\Python\Python313\Lib\site-packages\urllib3\connectionpool.py", line 534, in _make_request
    response = conn.getresponse()
  File "C:\Users\Ramiro\AppData\Local\Programs\Python\Python313\Lib\site-packages\urllib3\connection.py", line 516, in getresponse
    httplib_response = super().getresponse()
  File "C:\Users\Ramiro\AppData\Local\Programs\Python\Python313\Lib\http\client.py", line 1430, in getresponse
    response.begin()
    ~~~~~~~~~~~~~~^^
  File "C:\Users\Ramiro\AppData\Local\Programs\Python\Python313\Lib\http\client.py", line 331, in begin
    version, status, reason = self._read_status()
                              ~~~~~~~~~~~~~~~~~^^
  File "C:\Users\Ramiro\AppData\Local\Programs\Python\Python313\Lib\http\client.py", line 300, in _read_status
    raise RemoteDisconnected("Remote end closed connection without"
                             " response")
http.client.RemoteDisconnected: Remote end closed connection without response

During handling of the above exception, another exception occurred:

Traceback (most recent call last):
  File "c:\Users\Ramiro\OneDrive\Documentos\GitHub\Facultad\Ingenieria de Software\Practico Testing\Automatizar.py", line 684, in <module>
    automatizar.agregarProducto()
    ~~~~~~~~~~~~~~~~~~~~~~~~~~~^^
  File "c:\Users\Ramiro\OneDrive\Documentos\GitHub\Facultad\Ingenieria de Software\Practico Testing\Automatizar.py", line 179, in agregarProducto
    wait.until(EC.presence_of_element_located((By.CSS_SELECTOR, ".product-image-wrapper")))
    ~~~~~~~~~~^^^^^^^^^^^^^^^^^^^^^^^^^^^^^^^^^^^^^^^^^^^^^^^^^^^^^^^^^^^^^^^^^^^^^^^^^^^^^
  File "C:\Users\Ramiro\AppData\Local\Programs\Python\Python313\Lib\site-packages\selenium\webdriver\support\wait.py", line 129, in until
    value = method(self._driver)
  File "C:\Users\Ramiro\AppData\Local\Programs\Python\Python313\Lib\site-packages\selenium\webdriver\support\expected_conditions.py", line 104, in _predicate
    return driver.find_element(*locator)
           ~~~~~~~~~~~~~~~~~~~^^^^^^^^^^
  File "C:\Users\Ramiro\AppData\Local\Programs\Python\Python313\Lib\site-packages\selenium\webdriver\remote\webdriver.py", line 914, in find_element
    return self.execute(Command.FIND_ELEMENT, {"using": by, "value": value})["value"]
           ~~~~~~~~~~~~^^^^^^^^^^^^^^^^^^^^^^^^^^^^^^^^^^^^^^^^^^^^^^^^^^^^^
  File "C:\Users\Ramiro\AppData\Local\Programs\Python\Python313\Lib\site-packages\selenium\webdriver\remote\webdriver.py", line 445, in execute
    response = self.command_executor.execute(driver_command, params)
  File "C:\Users\Ramiro\AppData\Local\Programs\Python\Python313\Lib\site-packages\selenium\webdriver\remote\remote_connection.py", line 404, in execute
    return self._request(command_info[0], url, body=data)
           ~~~~~~~~~~~~~^^^^^^^^^^^^^^^^^^^^^^^^^^^^^^^^^
  File "C:\Users\Ramiro\AppData\Local\Programs\Python\Python313\Lib\site-packages\selenium\webdriver\remote\remote_connection.py", line 428, in _request
    response = self._conn.request(method, url, body=body, headers=headers, timeout=self._client_config.timeout)
  File "C:\Users\Ramiro\AppData\Local\Programs\Python\Python313\Lib\site-packages\urllib3\_request_methods.py", line 143, in request
    return self.request_encode_body(
           ~~~~~~~~~~~~~~~~~~~~~~~~^
        method, url, fields=fields, headers=headers, **urlopen_kw
        ^^^^^^^^^^^^^^^^^^^^^^^^^^^^^^^^^^^^^^^^^^^^^^^^^^^^^^^^^
    )
    ^
  File "C:\Users\Ramiro\AppData\Local\Programs\Python\Python313\Lib\site-packages\urllib3\_request_methods.py", line 278, in request_encode_body
    return self.urlopen(method, url, **extra_kw)
           ~~~~~~~~~~~~^^^^^^^^^^^^^^^^^^^^^^^^^
  File "C:\Users\Ramiro\AppData\Local\Programs\Python\Python313\Lib\site-packages\urllib3\poolmanager.py", line 443, in urlopen 
    response = conn.urlopen(method, u.request_uri, **kw)
  File "C:\Users\Ramiro\AppData\Local\Programs\Python\Python313\Lib\site-packages\urllib3\connectionpool.py", line 841, in urlopen
    retries = retries.increment(
        method, url, error=new_e, _pool=self, _stacktrace=sys.exc_info()[2]
    )
  File "C:\Users\Ramiro\AppData\Local\Programs\Python\Python313\Lib\site-packages\urllib3\util\retry.py", line 474, in increment
    raise reraise(type(error), error, _stacktrace)
          ~~~~~~~^^^^^^^^^^^^^^^^^^^^^^^^^^^^^^^^^
  File "C:\Users\Ramiro\AppData\Local\Programs\Python\Python313\Lib\site-packages\urllib3\util\util.py", line 38, in reraise    
    raise value.with_traceback(tb)
  File "C:\Users\Ramiro\AppData\Local\Programs\Python\Python313\Lib\site-packages\urllib3\connectionpool.py", line 787, in urlopen
    response = self._make_request(
        conn,
    ...<10 lines>...
        **response_kw,
    )
  File "C:\Users\Ramiro\AppData\Local\Programs\Python\Python313\Lib\site-packages\urllib3\connectionpool.py", line 534, in _make_request
    response = conn.getresponse()
  File "C:\Users\Ramiro\AppData\Local\Programs\Python\Python313\Lib\site-packages\urllib3\connection.py", line 516, in getresponse
    httplib_response = super().getresponse()
  File "C:\Users\Ramiro\AppData\Local\Programs\Python\Python313\Lib\http\client.py", line 1430, in getresponse
    response.begin()
    ~~~~~~~~~~~~~~^^
  File "C:\Users\Ramiro\AppData\Local\Programs\Python\Python313\Lib\http\client.py", line 331, in begin
    version, status, reason = self._read_status()
                              ~~~~~~~~~~~~~~~~~^^
  File "C:\Users\Ramiro\AppData\Local\Programs\Python\Python313\Lib\http\client.py", line 300, in _read_status
    raise RemoteDisconnected("Remote end closed connection without"
                             " response")
urllib3.exceptions.ProtocolError: ('Connection aborted.', RemoteDisconnected('Remote end closed connection without response')) 